/Users/sneilan/.local/share/virtualenvs/pytorch-rdpg-6CHzPIeI-python/lib/python3.8/site-packages/torch/autograd/__init__.py:173: UserWarning: Error detected in AddmmBackward0. Traceback of forward call that caused the error:
  File "/Users/sneilan/.pyenv/versions/3.8.5/lib/python3.8/runpy.py", line 194, in _run_module_as_main
    return _run_code(code, main_globals, None,
  File "/Users/sneilan/.pyenv/versions/3.8.5/lib/python3.8/runpy.py", line 87, in _run_code
    exec(code, run_globals)
  File "/Users/sneilan/.vscode/extensions/ms-python.python-2022.4.1/pythonFiles/lib/python/debugpy/__main__.py", line 45, in <module>
    cli.main()
  File "/Users/sneilan/.vscode/extensions/ms-python.python-2022.4.1/pythonFiles/lib/python/debugpy/../debugpy/server/cli.py", line 444, in main
    run()
  File "/Users/sneilan/.vscode/extensions/ms-python.python-2022.4.1/pythonFiles/lib/python/debugpy/../debugpy/server/cli.py", line 285, in run_file
    runpy.run_path(target_as_str, run_name=compat.force_str("__main__"))
  File "/Users/sneilan/.pyenv/versions/3.8.5/lib/python3.8/runpy.py", line 265, in run_path
    return _run_module_code(code, init_globals, run_name,
  File "/Users/sneilan/.pyenv/versions/3.8.5/lib/python3.8/runpy.py", line 97, in _run_module_code
    _run_code(code, mod_globals, init_globals,
  File "/Users/sneilan/.pyenv/versions/3.8.5/lib/python3.8/runpy.py", line 87, in _run_code
    exec(code, run_globals)
  File "main.py", line 57, in <module>
    rdpg.train(args.train_iter, args.checkpoint, args.debug)
  File "/Users/sneilan/workspace/ml_projects/rl_projects/pytorch-rdpg/rdpg.py", line 89, in train
    self.update_policy()
  File "/Users/sneilan/workspace/ml_projects/rl_projects/pytorch-rdpg/rdpg.py", line 155, in update_policy
    policy_loss = -self.agent.critic([ state0, action ])
  File "/Users/sneilan/.local/share/virtualenvs/pytorch-rdpg-6CHzPIeI-python/lib/python3.8/site-packages/torch/nn/modules/module.py", line 1110, in _call_impl
    return forward_call(*input, **kwargs)
  File "/Users/sneilan/workspace/ml_projects/rl_projects/pytorch-rdpg/model.py", line 80, in forward
    out = self.fc3(out)
  File "/Users/sneilan/.local/share/virtualenvs/pytorch-rdpg-6CHzPIeI-python/lib/python3.8/site-packages/torch/nn/modules/module.py", line 1110, in _call_impl
    return forward_call(*input, **kwargs)
  File "/Users/sneilan/.local/share/virtualenvs/pytorch-rdpg-6CHzPIeI-python/lib/python3.8/site-packages/torch/nn/modules/linear.py", line 103, in forward
    return F.linear(input, self.weight, self.bias)
 (Triggered internally at  /Users/distiller/project/pytorch/torch/csrc/autograd/python_anomaly_mode.cpp:104.)
  Variable._execution_engine.run_backward(  # Calls into the C++ engine to run the backward pass
Traceback (most recent call last):
  File "/Users/sneilan/.pyenv/versions/3.8.5/lib/python3.8/runpy.py", line 194, in _run_module_as_main
    return _run_code(code, main_globals, None,
  File "/Users/sneilan/.pyenv/versions/3.8.5/lib/python3.8/runpy.py", line 87, in _run_code
    exec(code, run_globals)
  File "/Users/sneilan/.vscode/extensions/ms-python.python-2022.4.1/pythonFiles/lib/python/debugpy/__main__.py", line 45, in <module>
    cli.main()
  File "/Users/sneilan/.vscode/extensions/ms-python.python-2022.4.1/pythonFiles/lib/python/debugpy/../debugpy/server/cli.py", line 444, in main
    run()
  File "/Users/sneilan/.vscode/extensions/ms-python.python-2022.4.1/pythonFiles/lib/python/debugpy/../debugpy/server/cli.py", line 285, in run_file
    runpy.run_path(target_as_str, run_name=compat.force_str("__main__"))
  File "/Users/sneilan/.pyenv/versions/3.8.5/lib/python3.8/runpy.py", line 265, in run_path
    return _run_module_code(code, init_globals, run_name,
  File "/Users/sneilan/.pyenv/versions/3.8.5/lib/python3.8/runpy.py", line 97, in _run_module_code
    _run_code(code, mod_globals, init_globals,
  File "/Users/sneilan/.pyenv/versions/3.8.5/lib/python3.8/runpy.py", line 87, in _run_code
    exec(code, run_globals)
  File "main.py", line 57, in <module>
    rdpg.train(args.train_iter, args.checkpoint, args.debug)
  File "/Users/sneilan/workspace/ml_projects/rl_projects/pytorch-rdpg/rdpg.py", line 89, in train
    self.update_policy()
  File "/Users/sneilan/workspace/ml_projects/rl_projects/pytorch-rdpg/rdpg.py", line 166, in update_policy
    policy_loss.backward()
  File "/Users/sneilan/.local/share/virtualenvs/pytorch-rdpg-6CHzPIeI-python/lib/python3.8/site-packages/torch/_tensor.py", line 363, in backward
    torch.autograd.backward(self, gradient, retain_graph, create_graph, inputs=inputs)
  File "/Users/sneilan/.local/share/virtualenvs/pytorch-rdpg-6CHzPIeI-python/lib/python3.8/site-packages/torch/autograd/__init__.py", line 173, in backward
    Variable._execution_engine.run_backward(  # Calls into the C++ engine to run the backward pass
RuntimeError: one of the variables needed for gradient computation has been modified by an inplace operation: [torch.FloatTensor [50, 1]], which is output 0 of AsStridedBackward0, is at version 2; expected version 1 instead. Hint: the backtrace further above shows the operation that failed to compute its gradient. The variable in question was changed in there or anywhere later. Good luck!
sneilan@Macbook-Pro-Spencer-Work pytorch-rdpg % 